Workbook

Sheet Solver Optimizer
A1: Player | B1: Pos | C1: Team | D1: Salary | E1: Projection | F1: Value | G1: Selected | H1: Slot
A2: ='Wide Receivers (WR)'!B16 | B2: ="WR" | C2: ='Wide Receivers (WR)'!C16 | D2: ='Wide Receivers (WR)'!E16 | E2: ='Wide Receivers (WR)'!J16 | F2: ='Wide Receivers (WR)'!K16 | G2: 1 | J2: Total Projection | K2: =SUMPRODUCT(G2:G191, E2:E191)
A3: ='Wide Receivers (WR)'!B6 | B3: ="WR" | C3: ='Wide Receivers (WR)'!C6 | D3: ='Wide Receivers (WR)'!E6 | E3: ='Wide Receivers (WR)'!J6 | F3: ='Wide Receivers (WR)'!K6 | G3: 1 | J3: Total Salary | K3: =SUMPRODUCT(G2:G191, D2:D191)
A4: ='Wide Receivers (WR)'!B5 | B4: ="WR" | C4: ='Wide Receivers (WR)'!C5 | D4: ='Wide Receivers (WR)'!E5 | E4: ='Wide Receivers (WR)'!J5 | F4: ='Wide Receivers (WR)'!K5 | G4: 1 | J4: Players Selected | K4: =SUM(G2:G191)
A5: ='Quarterbacks (QB)'!B6 | B5: ="QB" | C5: ='Quarterbacks (QB)'!C6 | D5: ='Quarterbacks (QB)'!E6 | E5: ='Quarterbacks (QB)'!L6 | F5: ='Quarterbacks (QB)'!M6 | G5: 1
A6: ='Running Backs (RB)'!B18 | B6: ="RB" | C6: ='Running Backs (RB)'!C18 | D6: ='Running Backs (RB)'!E18 | E6: ='Running Backs (RB)'!K18 | F6: ='Running Backs (RB)'!L18 | G6: 1 | J6: QB | K6: =SUMIFS(G2:G190,B2:B190,"QB")
A7: ='Running Backs (RB)'!B24 | B7: ="RB" | C7: ='Running Backs (RB)'!C24 | D7: ='Running Backs (RB)'!E24 | E7: ='Running Backs (RB)'!K24 | F7: ='Running Backs (RB)'!L24 | G7: 1 | J7: RB | K7: =SUMIFS(G2:G190,B2:B190,"RB")
A8: ='Running Backs (RB)'!B34 | B8: ="RB" | C8: ='Running Backs (RB)'!C34 | D8: ='Running Backs (RB)'!E34 | E8: ='Running Backs (RB)'!K34 | F8: ='Running Backs (RB)'!L34 | G8: 1 | J8: WR | K8: =SUMIFS(G2:G190,B2:B190,"WR")
A9: ='Tight Ends (TE)'!B5 | B9: ="TE" | C9: ='Tight Ends (TE)'!C5 | D9: ='Tight Ends (TE)'!E5 | E9: ='Tight Ends (TE)'!J5 | F9: ='Tight Ends (TE)'!K5 | G9: 1 | J9: TE | K9: =SUMIFS(G2:G190,B2:B190,"TE")
A10: ='Defenses (D_ST)'!B5 | B10: ="DEF" | C10: ='Defenses (D_ST)'!C5 | D10: ='Defenses (D_ST)'!E5 | E10: ='Defenses (D_ST)'!G5 | F10: ='Defenses (D_ST)'!H5 | G10: 1 | J10: DEF | K10: =SUMIFS(G3:G191,B3:B191,"DEF")
A11: ='Running Backs (RB)'!B13 | B11: ="RB" | C11: ='Running Backs (RB)'!C13 | D11: ='Running Backs (RB)'!E13 | E11: ='Running Backs (RB)'!K13 | F11: ='Running Backs (RB)'!L13 | G11: 0
A12: ='Quarterbacks (QB)'!B12 | B12: ="QB" | C12: ='Quarterbacks (QB)'!C12 | D12: ='Quarterbacks (QB)'!E12 | E12: ='Quarterbacks (QB)'!L12 | F12: ='Quarterbacks (QB)'!M12 | G12: 0
A13: ='Running Backs (RB)'!B5 | B13: ="RB" | C13: ='Running Backs (RB)'!C5 | D13: ='Running Backs (RB)'!E5 | E13: ='Running Backs (RB)'!K5 | F13: ='Running Backs (RB)'!L5 | G13: 0
A14: ='Running Backs (RB)'!B20 | B14: ="RB" | C14: ='Running Backs (RB)'!C20 | D14: ='Running Backs (RB)'!E20 | E14: ='Running Backs (RB)'!K20 | F14: ='Running Backs (RB)'!L20 | G14: 0
A15: ='Tight Ends (TE)'!B9 | B15: ="TE" | C15: ='Tight Ends (TE)'!C9 | D15: ='Tight Ends (TE)'!E9 | E15: ='Tight Ends (TE)'!J9 | F15: ='Tight Ends (TE)'!K9 | G15: 0
A16: ='Defenses (D_ST)'!B12 | B16: ="DEF" | C16: ='Defenses (D_ST)'!C12 | D16: ='Defenses (D_ST)'!E12 | E16: ='Defenses (D_ST)'!G12 | F16: ='Defenses (D_ST)'!H12 | G16: 0
A17: ='Quarterbacks (QB)'!B5 | B17: ="QB" | C17: ='Quarterbacks (QB)'!C5 | D17: ='Quarterbacks (QB)'!E5 | E17: ='Quarterbacks (QB)'!L5 | F17: ='Quarterbacks (QB)'!M5 | G17: 0
A18: ='Wide Receivers (WR)'!B42 | B18: ="WR" | C18: ='Wide Receivers (WR)'!C42 | D18: ='Wide Receivers (WR)'!E42 | E18: ='Wide Receivers (WR)'!J42 | F18: ='Wide Receivers (WR)'!K42 | G18: 0
A19: ='Running Backs (RB)'!B22 | B19: ="RB" | C19: ='Running Backs (RB)'!C22 | D19: ='Running Backs (RB)'!E22 | E19: ='Running Backs (RB)'!K22 | F19: ='Running Backs (RB)'!L22 | G19: 0
A20: ='Wide Receivers (WR)'!B18 | B20: ="WR" | C20: ='Wide Receivers (WR)'!C18 | D20: ='Wide Receivers (WR)'!E18 | E20: ='Wide Receivers (WR)'!J18 | F20: ='Wide Receivers (WR)'!K18 | G20: 0
A21: ='Tight Ends (TE)'!B7 | B21: ="TE" | C21: ='Tight Ends (TE)'!C7 | D21: ='Tight Ends (TE)'!E7 | E21: ='Tight Ends (TE)'!J7 | F21: ='Tight Ends (TE)'!K7 | G21: 0
A22: ='Tight Ends (TE)'!B12 | B22: ="TE" | C22: ='Tight Ends (TE)'!C12 | D22: ='Tight Ends (TE)'!E12 | E22: ='Tight Ends (TE)'!J12 | F22: ='Tight Ends (TE)'!K12 | G22: 0
A23: ='Defenses (D_ST)'!B17 | B23: ="DEF" | C23: ='Defenses (D_ST)'!C17 | D23: ='Defenses (D_ST)'!E17 | E23: ='Defenses (D_ST)'!G17 | F23: ='Defenses (D_ST)'!H17 | G23: 0
A24: ='Running Backs (RB)'!B37 | B24: ="RB" | C24: ='Running Backs (RB)'!C37 | D24: ='Running Backs (RB)'!E37 | E24: ='Running Backs (RB)'!K37 | F24: ='Running Backs (RB)'!L37 | G24: 0
A25: ='Running Backs (RB)'!B46 | B25: ="RB" | C25: ='Running Backs (RB)'!C46 | D25: ='Running Backs (RB)'!E46 | E25: ='Running Backs (RB)'!K46 | F25: ='Running Backs (RB)'!L46 | G25: 0
A26: ='Wide Receivers (WR)'!B8 | B26: ="WR" | C26: ='Wide Receivers (WR)'!C8 | D26: ='Wide Receivers (WR)'!E8 | E26: ='Wide Receivers (WR)'!J8 | F26: ='Wide Receivers (WR)'!K8 | G26: 0
A27: ='Wide Receivers (WR)'!B55 | B27: ="WR" | C27: ='Wide Receivers (WR)'!C55 | D27: ='Wide Receivers (WR)'!E55 | E27: ='Wide Receivers (WR)'!J55 | F27: ='Wide Receivers (WR)'!K55 | G27: 0
A28: ='Tight Ends (TE)'!B34 | B28: ="TE" | C28: ='Tight Ends (TE)'!C34 | D28: ='Tight Ends (TE)'!E34 | E28: ='Tight Ends (TE)'!J34 | F28: ='Tight Ends (TE)'!K34 | G28: 0
A29: ='Defenses (D_ST)'!B28 | B29: ="DEF" | C29: ='Defenses (D_ST)'!C28 | D29: ='Defenses (D_ST)'!E28 | E29: ='Defenses (D_ST)'!G28 | F29: ='Defenses (D_ST)'!H28 | G29: 0
A30: ='Quarterbacks (QB)'!B7 | B30: ="QB" | C30: ='Quarterbacks (QB)'!C7 | D30: ='Quarterbacks (QB)'!E7 | E30: ='Quarterbacks (QB)'!L7 | F30: ='Quarterbacks (QB)'!M7 | G30: 0
A31: ='Quarterbacks (QB)'!B8 | B31: ="QB" | C31: ='Quarterbacks (QB)'!C8 | D31: ='Quarterbacks (QB)'!E8 | E31: ='Quarterbacks (QB)'!L8 | F31: ='Quarterbacks (QB)'!M8 | G31: 0
A32: ='Quarterbacks (QB)'!B9 | B32: ="QB" | C32: ='Quarterbacks (QB)'!C9 | D32: ='Quarterbacks (QB)'!E9 | E32: ='Quarterbacks (QB)'!L9 | F32: ='Quarterbacks (QB)'!M9 | G32: 0
A33: ='Quarterbacks (QB)'!B10 | B33: ="QB" | C33: ='Quarterbacks (QB)'!C10 | D33: ='Quarterbacks (QB)'!E10 | E33: ='Quarterbacks (QB)'!L10 | F33: ='Quarterbacks (QB)'!M10 | G33: 0
A34: ='Quarterbacks (QB)'!B11 | B34: ="QB" | C34: ='Quarterbacks (QB)'!C11 | D34: ='Quarterbacks (QB)'!E11 | E34: ='Quarterbacks (QB)'!L11 | F34: ='Quarterbacks (QB)'!M11 | G34: 0
A35: ='Quarterbacks (QB)'!B13 | B35: ="QB" | C35: ='Quarterbacks (QB)'!C13 | D35: ='Quarterbacks (QB)'!E13 | E35: ='Quarterbacks (QB)'!L13 | F35: ='Quarterbacks (QB)'!M13 | G35: 0
A36: ='Quarterbacks (QB)'!B14 | B36: ="QB" | C36: ='Quarterbacks (QB)'!C14 | D36: ='Quarterbacks (QB)'!E14 | E36: ='Quarterbacks (QB)'!L14 | F36: ='Quarterbacks (QB)'!M14 | G36: 0
A37: ='Quarterbacks (QB)'!B15 | B37: ="QB" | C37: ='Quarterbacks (QB)'!C15 | D37: ='Quarterbacks (QB)'!E15 | E37: ='Quarterbacks (QB)'!L15 | F37: ='Quarterbacks (QB)'!M15 | G37: 0
A38: ='Quarterbacks (QB)'!B16 | B38: ="QB" | C38: ='Quarterbacks (QB)'!C16 | D38: ='Quarterbacks (QB)'!E16 | E38: ='Quarterbacks (QB)'!L16 | F38: ='Quarterbacks (QB)'!M16 | G38: 0
A39: ='Quarterbacks (QB)'!B17 | B39: ="QB" | C39: ='Quarterbacks (QB)'!C17 | D39: ='Quarterbacks (QB)'!E17 | E39: ='Quarterbacks (QB)'!L17 | F39: ='Quarterbacks (QB)'!M17 | G39: 0
A40: ='Quarterbacks (QB)'!B18 | B40: ="QB" | C40: ='Quarterbacks (QB)'!C18 | D40: ='Quarterbacks (QB)'!E18 | E40: ='Quarterbacks (QB)'!L18 | F40: ='Quarterbacks (QB)'!M18 | G40: 0
...

Sheet Dashboard & Prop Tracker
A1: NFL Projections & Sportsbook Prop Edge Model
A2: Dynamic prop tracker linking sportsbook lines to model baselines. Formulas automatically compute value edges and Over/Under signals.
A4: Total Slate Players | D4: Top QB Projected Score | G4: Top RB Projected Score | J4: Top WR Projected Score
A5: =COUNTA('Quarterbacks (QB)'!B5:B49)+COUNTA('Running Backs (RB)'!B5:B52)+COUNTA('Wide Receivers (WR)'!B5:B137)+COUNTA('Tight Ends (TE)'!B5:B50) | D5: =MAX('Quarterbacks (QB)'!L5:L49) | G5: =MAX('Running Backs (RB)'!K5:K52) | J5: =MAX('Wide Receivers (WR)'!J5:J137)
A8: Live Sportsbook Line Edge Tracker & Signal Generator
A9: Player Name | B9: Position | C9: Metric / Prop | D9: Model Projection | E9: Sportsbook Line | F9: Edge (Yards) | G9: Recommendation | H9: Edge % | I9: Suggested Stake
A10: Josh Allen | B10: QB | C10: Pass Yds | D10: =INDEX('Quarterbacks (QB)'!F:F,MATCH(A10,'Quarterbacks (QB)'!B:B,0)) | E10: 220.5 | F10: =D10-E10 | G10: =IF(F10>0, "OVER", IF(F10<0, "UNDER", "PUSH")) | H10: =ABS(F10)/E10 | I10: =IF(ABS(F10)>=10, "2.0 Units", IF(ABS(F10)>=5, "1.0 Unit", "Pass"))
A11: Joe Burrow | B11: QB | C11: Pass Yds | D11: =INDEX('Quarterbacks (QB)'!F:F,MATCH(A11,'Quarterbacks (QB)'!B:B,0)) | E11: 258.5 | F11: =D11-E11 | G11: =IF(F11>0, "OVER", IF(F11<0, "UNDER", "PUSH")) | H11: =ABS(F11)/E11 | I11: =IF(ABS(F11)>=10, "2.0 Units", IF(ABS(F11)>=5, "1.0 Unit", "Pass"))
A12: Jahmyr Gibbs | B12: RB | C12: Scrimmage Yds | D12: =INDEX('Running Backs (RB)'!F:F,MATCH(A12,'Running Backs (RB)'!B:B,0)) | E12: 88.5 | F12: =D12-E12 | G12: =IF(F12>0, "OVER", IF(F12<0, "UNDER", "PUSH")) | H12: =ABS(F12)/E12 | I12: =IF(ABS(F12)>=10, "2.0 Units", IF(ABS(F12)>=5, "1.0 Unit", "Pass"))
A13: Jonathan Taylor | B13: RB | C13: Scrimmage Yds | D13: =INDEX('Running Backs (RB)'!F:F,MATCH(A13,'Running Backs (RB)'!B:B,0)) | E13: 95.5 | F13: =D13-E13 | G13: =IF(F13>0, "OVER", IF(F13<0, "UNDER", "PUSH")) | H13: =ABS(F13)/E13 | I13: =IF(ABS(F13)>=10, "2.0 Units", IF(ABS(F13)>=5, "1.0 Unit", "Pass"))
A14: Ja'Marr Chase | B14: WR | C14: Rec Yds | D14: =INDEX('Wide Receivers (WR)'!F:F,MATCH(A14,'Wide Receivers (WR)'!B:B,0)) | E14: 85.5 | F14: =D14-E14 | G14: =IF(F14>0, "OVER", IF(F14<0, "UNDER", "PUSH")) | H14: =ABS(F14)/E14 | I14: =IF(ABS(F14)>=10, "2.0 Units", IF(ABS(F14)>=5, "1.0 Unit", "Pass"))
A15: Amon-Ra St. Brown | B15: WR | C15: Rec Yds | D15: =INDEX('Wide Receivers (WR)'!F:F,MATCH(A15,'Wide Receivers (WR)'!B:B,0)) | E15: 79.5 | F15: =D15-E15 | G15: =IF(F15>0, "OVER", IF(F15<0, "UNDER", "PUSH")) | H15: =ABS(F15)/E15 | I15: =IF(ABS(F15)>=10, "2.0 Units", IF(ABS(F15)>=5, "1.0 Unit", "Pass"))
A16: Drake London | B16: WR | C16: Rec Yds | D16: =INDEX('Wide Receivers (WR)'!F:F,MATCH(A16,'Wide Receivers (WR)'!B:B,0)) | E16: 68.5 | F16: =D16-E16 | G16: =IF(F16>0, "OVER", IF(F16<0, "UNDER", "PUSH")) | H16: =ABS(F16)/E16 | I16: =IF(ABS(F16)>=10, "2.0 Units", IF(ABS(F16)>=5, "1.0 Unit", "Pass"))
A17: Trey McBride | B17: TE | C17: Rec Yds | D17: =INDEX('Tight Ends (TE)'!F:F,MATCH(A17,'Tight Ends (TE)'!B:B,0)) | E17: 62.5 | F17: =D17-E17 | G17: =IF(F17>0, "OVER", IF(F17<0, "UNDER", "PUSH")) | H17: =ABS(F17)/E17 | I17: =IF(ABS(F17)>=10, "2.0 Units", IF(ABS(F17)>=5, "1.0 Unit", "Pass"))
A20: Week 1 cleanup | B20: Removed inactive/out players and players outside the top-2 depth-chart role; see 'Removed Players' for the audit trail.

Sheet Quarterbacks (QB)
A1: Quarterbacks (QB) - Sportsbook Props Projection Model
A4: Rank | B4: Player Name | C4: Team | D4: Opponent | E4: Salary | F4: Pass Yds Prop | G4: Pass TD Odds | H4: Rush Yds Prop | I4: Rush TD Odds | J4: INT Prop | K4: Implied Pass TD % | L4: Implied Rush TD % | M4: Projected Score | N4: ESPN Projection | O4: Weighted Projection | P4: Value | Q4: Projected Ownership
A5: 1 | B5: Josh Allen | C5: BUF | D5: BAL | E5: 9400 | G5: -220 | I5: -135 | K5: 0.6875 | L5: 0.5745 | M5: 6.2 | N5: 31.4 | O5: 16.28 | P5: 1.73 | Q5: 0.0393
A6: 2 | B6: Jared Goff | C6: DET | D6: MIN | E6: 7800 | F6: 265.5 | G6: -136 | I6: 1750 | K6: 0.5763 | L6: 0.0541 | M6: 13.25 | N6: 23.1 | O6: 17.19 | P6: 2.2 | Q6: 0.0629
A7: 3 | B7: Joe Burrow | C7: CIN | D7: TEN | E7: 8300 | G7: -220 | I7: 600 | K7: 0.6875 | L7: 0.1429 | M7: 3.61 | N7: 31.7 | O7: 14.84 | P7: 1.79 | Q7: 0.0308
A8: 4 | B8: Drake Maye | C8: NE | D8: MIA | E8: 8200 | G8: -220 | I8: 275 | K8: 0.6875 | L8: 0.2667 | M8: 4.35 | N8: 33.1 | O8: 15.85 | P8: 1.93 | Q8: 0.0419
A9: 5 | B9: Lamar Jackson | C9: BAL | D9: BUF | E9: 8500 | G9: -220 | I9: 220 | K9: 0.6875 | L9: 0.3125 | M9: 4.62 | N9: 30.2 | O9: 14.86 | P9: 1.75 | Q9: 0.03
A10: 6 | B10: Trevor Lawrence | C10: JAC | D10: IND | E10: 7700 | G10: -220 | I10: 250 | K10: 0.6875 | L10: 0.2857 | M10: 4.46 | N10: 29.6 | O10: 14.52 | P10: 1.89 | Q10: 0.0307
A11: 7 | B11: Kirk Cousins | C11: LV | D11: NYJ | E11: 6800 | G11: -220 | I11: 1300 | K11: 0.6875 | L11: 0.0714 | M11: 3.18 | N11: 24 | O11: 11.51 | P11: 1.69 | Q11: 0.0105
A12: 8 | B12: Matthew Stafford | C12: LAR | D12: LAC | E12: 7600 | G12: -220 | I12: 1900 | K12: 0.6875 | L12: 0.05 | M12: 3.05 | N12: 24.6 | O12: 11.67 | P12: 1.54 | Q12: 0.0099
A13: 9 | B13: Dak Prescott | C13: DAL | D13: ARI | E13: 8000 | G13: -220 | I13: 400 | K13: 0.6875 | L13: 0.2 | M13: 3.95 | N13: 27.6 | O13: 13.41 | P13: 1.68 | Q13: 0.0199
A14: 10 | B14: Patrick Mahomes | C14: KC | D14: DEN | E14: 7900 | G14: -220 | I14: 450 | K14: 0.6875 | L14: 0.1818 | M14: 3.84 | N14: 19.8 | O14: 10.22 | P14: 1.29 | Q14: 0.0037
A15: 11 | B15: Michael Penix Jr. | C15: ATL | D15: TB | E15: 6900 | G15: -220 | I15: 700 | K15: 0.6875 | L15: 0.125 | M15: 3.5 | N15: 22 | O15: 10.9 | P15: 1.58 | Q15: 0.0072
A16: 12 | B16: Aaron Rodgers | C16: PIT | D16: CLE | E16: 7200 | G16: -220 | I16: 1000 | K16: 0.6875 | L16: 0.0909 | M16: 3.3 | N16: 21.8 | O16: 10.7 | P16: 1.49 | Q16: 0.006
A17: 13 | B17: Jacoby Brissett | C17: ARI | D17: DAL | E17: 7100 | G17: -220 | I17: 650 | K17: 0.6875 | L17: 0.1333 | M17: 3.55 | N17: 22.3 | O17: 11.05 | P17: 1.56 | Q17: 0.0077
A18: 14 | B18: Deshaun Watson | C18: CLE | D18: PIT | E18: 7300 | G18: -220 | I18: 400 | K18: 0.6875 | L18: 0.2 | M18: 3.95 | N18: 17.9 | O18: 9.53 | P18: 1.31 | Q18: 0.0022
... A23: 19 | B23: Tyler Huntley | C23: BAL | D23: BUF | E23: 6700 | G23: -220 | I23: 300 | K23: 0.6875 | L23: 0.25 | M23: 4.25 | N23: 0 | O23: 4.25 | P23: 0.63 | Q23: 0
A24: 20 | B24: Jake Browning | C24: LAC | D24: LAR | E24: 6000 | G24: -220 | K24: 0.6875 | L24: 0.1053 | M24: 2.75 | N24: 0 | O24: 2.75 | P24: 0.46 | Q24: 0
A25: 21 | B25: Cam Ward | C25: TEN | D25: CIN | E25: 6500 | G25: -220 | I25: 400 | K25: 0.6875 | L25: 0.2 | M25: 3.95 | N25: 15 | O25: 8.37 | P25: 1.29 | Q25: 0.0003
A26: 22 | B26: Kyler Murray | C26: MIN | D26: DET | E26: 7400 | F26: 215.5 | G26: 134 | I26: 500 | K26: 0.4274 | L26: 0.1667 | M26: 11.33 | N26: 24.1 | O26: 16.44 | P26: 2.22 | Q26: 0.056
A27: 23 | B27: Baker Mayfield | C27: TB | D27: ATL | E27: 7000 | G27: -220 | I27: 300 | K27: 0.6875 | L27: 0.25 | M27: 4.25 | N27: 22.1 | O27: 11.39 | P27: 1.63 | Q27: 0.0095
A28: 24 | B28: Daniel Jones | C28: IND | D28: JAC | E28: 6600 | G28: -220 | I28: 650 | K28: 0.6875 | L28: 0.1333 | M28: 3.55 | N28: 15.9 | O28: 8.49 | P28: 1.29 | Q28: 0.0004
A29: 25 | B29: Josh Johnson | C29: CIN | D29: TEN | E29: 6000 | G29: -220 | K29: 0.6875 | L29: 0 | M29: 2.75 | N29: 0 | O29: 2.75 | P29: 0.46 | Q29: 0
A30: 26 | B30: Carson Wentz | C30: MIN | D30: DET | E30: 6000 | G30: -220 | K30: 0.6875 | L30: 0 | M30: 2.75 | N30: 0 | O30: 2.75 | P30: 0.46 | Q30: 0
A31: 27 | B31: Jalon Daniels | C31: TB | D31: ATL | E31: 6300 | G31: -220 | K31: 0.6875 | L31: 0.1538 | M31: 2.75 | N31: 0 | O31: 2.75 | P31: 0.44 | Q31: 0
A32: 28 | B32: Dillon Gabriel | C32: CLE | D32: PIT | E32: 6000 | G32: -220 | K32: 0.6875 | L32: 0 | M32: 2.75 | N32: 0 | O32: 2.75 | P32: 0.46 | Q32: 0
A33: 29 | B33: Shane Buechele | C33: BUF | D33: BAL | E33: 6000 | G33: -220 | K33: 0.6875 | L33: 0 | M33: 2.75 | N33: 0 | O33: 2.75 | P33: 0.46 | Q33: 0
A34: 30 | B34: Tommy DeVito | C34: NE | D34: MIA | E34: 6000 | G34: -220 | K34: 0.6875 | L34: 0 | M34: 2.75 | N34: 0 | O34: 2.75 | P34: 0.46 | Q34: 0
A35: 31 | B35: Max Brosmer | C35: MIN | D35: DET | E35: 6000 | G35: -220 | K35: 0.6875 | L35: 0 | M35: 2.75 | N35: 0 | O35: 2.75 | P35: 0.46 | Q35: 0
A36: 32 | B36: Fernando Mendoza | C36: LV | D36: NYJ | E36: 6400 | G36: -220 | K36: 0.6875 | L36: 0 | M36: 2.75 | N36: 0 | O36: 2.75 | P36: 0.43 | Q36: 0
A37: 33 | B37: Stetson Bennett IV | C37: LAR | D37: LAC | E37: 6000 | G37: -220 | K37: 0.6875 | L37: 0 | M37: 2.75 | N37: 0 | O37: 2.75 | P37: 0.46 | Q37: 0
A38: 34 | B38: Jack Strand | C38: ATL | D38: TB | E38: 6000 | G38: -220 | K38: 0.6875 | L38: 0 | M38: 2.75 | N38: 0 | O38: 2.75 | P38: 0.46 | Q38: 0
A39: 35 | B39: Tua Tagovailoa | C39: ATL | D39: TB | E39: 6200 | G39: -220 | K39: 0.6875 | L39: 0.0833 | M39: 2.75 | N39: 0 | O39: 2.75 | P39: 0.44 | Q39: 0
A40: 36 | B40: Mason Rudolph | C40: PIT | D40: CLE | E40: 6000 | G40: -220 | K40: 0.6875 | L40: 0 | M40: 2.75 | N40: 0 | O40: 2.75 | P40: 0.46 | Q40: 0
... A93: 89 | B93: DJ Uiagalelei | C93: LAC | D93: KC | E93: 6000 | G93: -220 | K93: 0.6875 | L93: 0 | M93: 2.75 | N93: 0 | O93: 2.75 | P93: 0.46 | Q93: 0

Sheet Running Backs (RB)
A1: Running Backs (RB) - Sportsbook Props Projection Model
A4: Rank | B4: Player Name | C4: Team | D4: Opponent | E4: Salary | F4: Rush Yds Prop | G4: Anytime TD Odds | H4: Receptions Prop | I4: Rec Yds Prop | J4: Implied TD % | K4: Projected Score | L4: ESPN Projection | M4: Weighted Projection | N4: Value | O4: Projected Ownership
A5: 1 | B5: Jahmyr Gibbs | C5: DET | D5: MIN | E5: 9300 | F5: 84.5 | G5: -250 | H5: 4.5 | I5: 35.5 | J5: 0.7143 | K5: 18.54 | L5: 26 | M5: 21.52 | N5: 2.31 | O5: 0.4069
A6: 2 | B6: Kenneth Walker III | C6: KC | D6: DEN | E6: 9000 | G6: -125 | J6: 0.5556 | K6: 3.33 | L6: 21.4 | M6: 10.56 | N6: 1.17 | O6: 0.0386
A7: 3 | B7: Bijan Robinson | C7: ATL | D7: TB | E7: 8800 | G7: -205 | J7: 0.6721 | K7: 4.03 | L7: 20.3 | M7: 10.54 | N7: 1.2 | O7: 0.0394
A8: 4 | B8: James Cook III | C8: BUF | D8: BAL | E8: 8400 | G8: -150 | J8: 0.6 | K8: 3.6 | L8: 20.7 | M8: 10.44 | N8: 1.24 | O8: 0.0404
A9: 5 | B9: Jonathan Taylor | C9: IND | D9: JAC | E9: 8300 | G9: -167 | J9: 0.6255 | K9: 3.75 | L9: 17.1 | M9: 9.09 | N9: 1.1 | O9: 0.0241
A10: 6 | B10: Javonte Williams | C10: DAL | D10: ARI | E10: 7500 | G10: -250 | J10: 0.7143 | K10: 4.29 | L10: 21.8 | M10: 11.29 | N10: 1.51 | O10: 0.0624
A11: 7 | B11: Derrick Henry | C11: BAL | D11: BUF | E11: 8500 | G11: -205 | J11: 0.6721 | K11: 4.03 | L11: 20.9 | M11: 10.78 | N11: 1.27 | O11: 0.0448
A12: 8 | B12: Kyren Williams | C12: LAR | D12: LAC | E12: 7600 | G12: -160 | J12: 0.6154 | K12: 3.69 | L12: 18.7 | M12: 9.7 | N12: 1.28 | O12: 0.0348
A13: 9 | B13: Jaylen Warren | C13: PIT | D13: CLE | E13: 7400 | G13: -135 | J13: 0.5745 | K13: 3.45 | L13: 16.9 | M13: 8.83 | N13: 1.19 | O13: 0.0249
A14: 10 | B14: Ashton Jeanty | C14: LV | D14: NYJ | E14: 7200 | G14: -125 | J14: 0.5556 | K14: 3.33 | L14: 17 | M14: 8.8 | N14: 1.22 | O14: 0.0254
A15: 11 | B15: Bucky Irving | C15: TB | D15: ATL | E15: 7300 | G15: -130 | J15: 0.5652 | K15: 3.39 | L15: 18.7 | M15: 9.51 | N15: 1.3 | O15: 0.034
A16: 12 | B16: Ollie Gordon II | C16: MIA | D16: NE | E16: 6400 | G16: 130 | J16: 0.4348 | K16: 2.61 | L16: 15.9 | M16: 7.93 | N16: 1.24 | O16: 0.0192
A17: 13 | B17: Bhayshul Tuten | C17: JAC | D17: IND | E17: 6900 | G17: -115 | J17: 0.5349 | K17: 3.21 | L17: 16 | M17: 8.33 | N17: 1.21 | O17: 0.0215
... A24: 20 | B24: Chase Brown | C24: CIN | D24: TEN | E24: 7100 | G24: 105 | J24: 0.4878 | K24: 2.93 | L24: 17.3 | M24: 8.68 | N24: 1.22 | O24: 0.0245
A25: 21 | B25: James Conner | C25: ARI | D25: DAL | E25: 5100 | J25: 0.3846 | K25: 0 | L25: 0 | M25: 0 | N25: 0 | O25: 0.08
A26: 22 | B26: Jordan Mason | C26: MIN | D26: DET | E26: 6000 | G26: 140 | J26: 0.4167 | K26: 2.5 | L26: 10.5 | M26: 5.7 | N26: 0.95 | O26: 0.0039
A27: 23 | B27: Blake Corum | C27: LAR | D27: LAC | E27: 5900 | G27: 135 | J27: 0.4255 | K27: 2.55 | L27: 12.6 | M27: 6.57 | N27: 1.11 | O27: 0.0088
A28: 24 | B28: RJ Harvey | C28: DEN | D28: KC | E28: 5500 | G28: 180 | J28: 0.3571 | K28: 2.14 | L28: 8.6 | M28: 4.73 | N28: 0.86 | O28: 0.001
A29: 25 | B29: Jeremiyah Love | C29: ARI | D29: DAL | E29: 5900 | G29: 100 | J29: 0.5 | K29: 3 | L29: 12.4 | M29: 6.76 | N29: 1.15 | O29: 0.0102
A30: 26 | B30: Omarion Hampton | C30: LAC | D30: LAR | E30: 5800 | G30: 205 | J30: 0.3279 | K30: 1.97 | L30: 8.9 | M30: 4.74 | N30: 0.82 | O30: 0.0009
A31: 27 | B31: Brian Robinson Jr. | C31: ATL | D31: TB | E31: 5300 | G31: 300 | J31: 0.25 | K31: 1.5 | L31: 6.4 | M31: 3.46 | N31: 0.65 | O31: 0
A32: 28 | B32: Audric Estime | C32: CLE | D32: PIT | E32: 4300 | G32: 900 | J32: 0.1 | K32: 0.6 | L32: 0 | M32: 0.6 | N32: 0.14 | O32: 0
A33: 29 | B33: J.K. Dobbins | C33: DEN | D33: KC | E33: 5700 | G33: 140 | J33: 0.4167 | K33: 2.5 | L33: 6.9 | M33: 4.26 | N33: 0.75 | O33: 0.0002
A34: 30 | B34: Trey Benson | C34: ARI | D34: DAL | E34: 4000 | J34: 0.1667 | K34: 0 | L34: 0 | M34: 0 | N34: 0 | O34: 0.08
A35: 31 | B35: Jonah Coleman | C35: DEN | D35: KC | E35: 5300 | G35: 350 | J35: 0.2222 | K35: 1.33 | L35: 8.2 | M35: 4.08 | N35: 0.77 | O35: 0
A36: 32 | B36: De'Von Achane | C36: MIA | D36: NE | E36: 4000 | J36: 0.2083 | K36: 0 | L36: 0 | M36: 0 | N36: 0 | O36: 0.08
A37: 33 | B37: Kimani Vidal | C37: LAC | D37: LAR | E37: 5100 | G37: 300 | J37: 0.25 | K37: 1.5 | L37: 8.2 | M37: 4.18 | N37: 0.82 | O37: 0.0001
A38: 34 | B38: Isiah Pacheco | C38: DET | D38: MIN | E38: 4000 | J38: 0.2128 | K38: 0 | L38: 0 | M38: 0 | N38: 0 | O38: 0.08
A39: 35 | B39: Tyler Allgeier | C39: ARI | D39: DAL | E39: 5700 | G39: 170 | J39: 0.3704 | K39: 2.22 | L39: 8.5 | M39: 4.73 | N39: 0.83 | O39: 0.0009
A40: 36 | B40: Samaje Perine | C40: CIN | D40: TEN | E40: 5000 | G40: 220 | J40: 0.3125 | K40: 1.88 | L40: 7.7 | M40: 4.21 | N40: 0.84 | O40: 0.0001
A41: 37 | B41: Ty Johnson | C41: BUF | D41: BAL | E41: 5000 | G41: 450 | J41: 0.1818 | K41: 1.09 | L41: 5.7 | M41: 2.93 | N41: 0.59 | O41: 0
A42: 38 | B42: Rico Dowdle | C42: PIT | D42: CLE | E42: 5400 | G42: 270 | J42: 0.2703 | K42: 1.62 | L42: 9.5 | M42: 4.77 | N42: 0.88 | O42: 0.0011
A43: 39 | B43: TreVeyon Henderson | C43: NE | D43: MIA | E43: 5400 | G43: 260 | J43: 0.2778 | K43: 1.67 | L43: 7 | M43: 3.8 | N43: 0.7 | O43: 0
A44: 40 | B44: Keaton Mitchell | C44: LAC | D44: LAR | E44: 4900 | G44: 350 | J44: 0.2222 | K44: 1.33 | L44: 5.8 | M44: 3.12 | N44: 0.64 | O44: 0
A45: 41 | B45: Sean Tucker | C45: TB | D45: ATL | E45: 4400 | G45: 350 | J45: 0.2222 | K45: 1.33 | L45: 2.1 | M45: 1.64 | N45: 0.37 | O45: 0
A46: 42 | B46: Chris Rodriguez Jr. | C46: JAC | D46: IND | E46: 5200 | G46: 130 | J46: 0.4348 | K46: 2.61 | L46: 7.2 | M46: 4.45 | N46: 0.85 | O46: 0.0005
A47: 43 | B47: Malik Davis | C47: DAL | D47: ARI | E47: 4000 | J47: 0.16 | K47: 0 | L47: 0 | M47: 0 | N47: 0 | O47: 0.08
A48: 44 | B48: Kenny Gainwell | C48: TB | D48: ATL | E48: 5200 | G48: 300 | J48: 0.25 | K48: 1.5 | L48: 7.9 | M48: 4.06 | N48: 0.78 | O48: 0
...

Sheet Wide Receivers (WR)
A1: Wide Receivers (WR) - Sportsbook Props Projection Model
A4: Rank | B4: Player Name | C4: Team | D4: Opponent | E4: Salary | F4: Rec Yds Prop | G4: Anytime TD Odds | H4: Receptions Prop | I4: Implied TD % | J4: Projected Score | K4: ESPN Projection | L4: Weighted Projection | M4: Value | N4: Projected Ownership
A5: 1 | B5: CeeDee Lamb | C5: DAL | D5: ARI | E5: 8900 | G5: 100 | I5: 0.5 | J5: 3 | K5: 18.9 | L5: 9.36 | M5: 1.05 | N5: 0.0608
A6: 2 | B6: Amon-Ra St. Brown | C6: DET | D6: MIN | E6: 8500 | F6: 78.5 | G6: 125 | H6: 6.5 | I6: 0.4444 | J6: 13.77 | K6: 16.3 | L6: 14.78 | M6: 1.74 | N6: 0.3334
A7: 3 | B7: Zay Flowers | C7: BAL | D7: BUF | E7: 8000 | G7: 140 | I7: 0.4167 | J7: 2.5 | K7: 19 | L7: 9.1 | M7: 1.14 | N7: 0.0625
A8: 4 | B8: Omar Cooper Jr. | C8: NYJ | D8: LV | E8: 5900 | G8: 235 | I8: 0.2985 | J8: 1.79 | K8: 9.9 | L8: 5.03 | M8: 0.85 | N8: 0.0039
A9: 5 | B9: Puka Nacua | C9: LAR | D9: LAC | E9: 9100 | G9: -135 | I9: 0.5745 | J9: 3.45 | K9: 21.2 | L9: 10.55 | M9: 1.16 | N9: 0.0932
A10: 6 | B10: Davante Adams | C10: LAR | D10: LAC | E10: 7300 | I10: 0.3846 | J10: 0 | K10: 0 | L10: 0 | M10: 0 | N10: 0.08
A11: 7 | B11: Tee Higgins | C11: CIN | D11: TEN | E11: 7100 | G11: 110 | I11: 0.4762 | J11: 2.86 | K11: 14.4 | L11: 7.47 | M11: 1.05 | N11: 0.0317
A12: 8 | B12: Parker Washington | C12: JAC | D12: IND | E12: 7200 | G12: 115 | I12: 0.4651 | J12: 2.79 | K12: 15.7 | L12: 7.95 | M12: 1.1 | N12: 0.041
A13: 9 | B13: Drake London | C13: ATL | D13: TB | E13: 7700 | G13: 115 | I13: 0.4651 | J13: 2.79 | K13: 17 | L13: 8.47 | M13: 1.1 | N13: 0.0491
A14: 10 | B14: Ja'Marr Chase | C14: CIN | D14: TEN | E14: 8700 | G14: -110 | I14: 0.5238 | J14: 3.14 | K14: 20.3 | L14: 10.01 | M14: 1.15 | N14: 0.0811
A15: 11 | B15: Tre Tucker | C15: LV | D15: NYJ | E15: 6100 | G15: 200 | I15: 0.3333 | J15: 2 | K15: 10.3 | L15: 5.32 | M15: 0.87 | N15: 0.0058
A16: 12 | B16: Jameson Williams | C16: DET | D16: MIN | E16: 6300 | F16: 50.5 | G16: 210 | H16: 3.5 | I16: 0.3226 | J16: 8.74 | K16: 10.5 | L16: 9.44 | M16: 1.5 | N16: 0.0985
A17: 13 | B17: Garrett Wilson | C17: NYJ | D17: LV | E17: 7000 | G17: 140 | I17: 0.4167 | J17: 2.5 | K17: 12.9 | L17: 6.66 | M17: 0.95 | N17: 0.0187
A18: 14 | B18: Justin Jefferson | C18: MIN | D18: DET | E18: 7900 | F18: 74.5 | G18: 180 | H18: 5.5 | I18: 0.3571 | J18: 12.34 | K18: 16.5 | L18: 14.01 | M18: 1.77 | N18: 0.3061
A19: 15 | B19: George Pickens | C19: DAL | D19: ARI | E19: 7800 | G19: 130 | I19: 0.4348 | J19: 2.61 | K19: 13 | L19: 6.77 | M19: 0.87 | N19: 0.0176
A20: 16 | B20: Tyquan Thornton | C20: KC | D20: DEN | E20: 4000 | I20: 0.3922 | J20: 0 | K20: 0 | L20: 0 | M20: 0 | N20: 0.08
A21: 17 | B21: Rashee Rice | C21: KC | D21: DEN | E21: 6900 | G21: 160 | I21: 0.3846 | J21: 2.31 | K21: 11.4 | L21: 5.94 | M21: 0.86 | N21: 0.0102
A22: 18 | B22: Keon Coleman | C22: BUF | D22: BAL | E22: 5600 | G22: 220 | I22: 0.3125 | J22: 1.88 | K22: 6.3 | L22: 3.65 | M22: 0.65 | N22: 0
A23: 19 | B23: Denzel Boston | C23: CLE | D23: PIT | E23: 5600 | G23: 250 | I23: 0.2857 | J23: 1.71 | K23: 10.9 | L23: 5.39 | M23: 0.96 | N23: 0.0072
A24: 20 | B24: Emeka Egbuka | C24: TB | D24: ATL | E24: 6000 | G24: 140 | I24: 0.4167 | J24: 2.5 | K24: 12.3 | L24: 6.42 | M24: 1.07 | N24: 0.0189
A25: 21 | B25: DK Metcalf | C25: PIT | D25: CLE | E25: 6600 | G25: 150 | I25: 0.4 | J25: 2.4 | K25: 11.6 | L25: 6.08 | M25: 0.92 | N25: 0.0124
A26: 22 | B26: Michael Wilson | C26: ARI | D26: DAL | E26: 6200 | G26: 150 | I26: 0.4 | J26: 2.4 | K26: 11.8 | L26: 6.16 | M26: 0.99 | N26: 0.0144
A27: 23 | B27: Carnell Tate | C27: TEN | D27: CIN | E27: 5900 | G27: 240 | I27: 0.2941 | J27: 1.76 | K27: 10.7 | L27: 5.34 | M27: 0.9 | N27: 0.0063
A28: 24 | B28: Caleb Douglas | C28: MIA | D28: NE | E28: 5300 | G28: 200 | I28: 0.3333 | J28: 2 | K28: 8.6 | L28: 4.64 | M28: 0.88 | N28: 0.002
A29: 25 | B29: Romeo Doubs | C29: NE | D29: MIA | E29: 5700 | I29: 0.2857 | J29: 0 | K29: 0 | L29: 0 | M29: 0 | N29: 0.08
A30: 26 | B30: Jakobi Meyers | C30: JAC | D30: IND | E30: 5900 | G30: 150 | I30: 0.4 | J30: 2.4 | K30: 10.2 | L30: 5.52 | M30: 0.94 | N30: 0.0079
A31: 27 | B31: DJ Moore | C31: BUF | D31: BAL | E31: 6700 | G31: 155 | I31: 0.3922 | J31: 2.35 | K31: 13 | L31: 6.61 | M31: 0.99 | N31: 0.019
A32: 28 | B32: Keenan Allen | C32: IND | D32: JAC | E32: 5800 | G32: 290 | I32: 0.2564 | J32: 1.54 | K32: 8.1 | L32: 4.16 | M32: 0.72 | N32: 0.0002
A33: 29 | B33: Jaylen Waddle | C33: DEN | D33: KC | E33: 6400 | G33: 210 | I33: 0.3226 | J33: 1.94 | K33: 9.7 | L33: 5.04 | M33: 0.79 | N33: 0.0036
A34: 30 | B34: DeMario Douglas | C34: NE | D34: MIA | E34: 5100 | G34: 240 | I34: 0.2941 | J34: 1.76 | K34: 9.9 | L34: 5.02 | M34: 0.98 | N34: 0.0046
A35: 31 | B35: Roman Wilson | C35: PIT | D35: CLE | E35: 4000 | I35: 0.2041 | J35: 0 | K35: 0 | L35: 0 | M35: 0 | N35: 0.08
A36: 32 | B36: Germie Bernard | C36: PIT | D36: CLE | E36: 5000 | G36: 220 | I36: 0.3125 | J36: 1.88 | K36: 9.7 | L36: 5 | M36: 1 | N36: 0.0046
A37: 33 | B37: Khalil Shakir | C37: BUF | D37: BAL | E37: 5700 | G37: 200 | I37: 0.3333 | J37: 2 | K37: 8.6 | L37: 4.64 | M37: 0.81 | N37: 0.0018
A38: 34 | B38: Malik Washington | C38: MIA | D38: NE | E38: 5500 | G38: 300 | I38: 0.25 | J38: 1.5 | K38: 9.8 | L38: 4.82 | M38: 0.88 | N38: 0.0029
A39: 35 | B39: KC Concepcion Jr. | C39: CLE | D39: PIT | E39: 5800 | G39: 235 | I39: 0.2985 | J39: 1.79 | K39: 9.3 | L39: 4.79 | M39: 0.83 | N39: 0.0025
A40: 36 | B40: Ryan Flournoy | C40: DAL | D40: ARI | E40: 5200 | G40: 250 | I40: 0.2857 | J40: 1.71 | K40: 8.4 | L40: 4.39 | M40: 0.84 | N40: 0.0009
A41: 37 | B41: Mack Hollins | C41: NE | D41: MIA | E41: 5600 | I41: 0.1538 | J41: 0 | K41: 0 | L41: 0 | M41: 0 | N41: 0.08
A42: 38 | B42: Pat Bryant | C42: DEN | D42: KC | E42: 4000 | I42: 0.3448 | J42: 0 | K42: 0 | L42: 0 | M42: 0 | N42: 0.08
...

Sheet Tight Ends (TE)
A1: Tight Ends (TE) - Sportsbook Props Projection Model
A4: Rank | B4: Player Name | C4: Team | D4: Opponent | E4: Salary | F4: Rec Yds Prop | G4: Anytime TD Odds | H4: Receptions Prop | I4: Implied TD % | J4: Projected Score | K4: ESPN Projection | L4: Weighted Projection | M4: Value | N4: Projected Ownership
A5: 1 | B5: Brock Bowers | C5: LV | D5: NYJ | E5: 7800 | G5: 115 | I5: 0.4651 | J5: 2.79 | K5: 14.8 | L5: 7.59 | M5: 0.97 | N5: 0.0414
A6: 2 | B6: Trey McBride | C6: ARI | D6: DAL | E6: 7300 | G6: 100 | I6: 0.5 | J6: 3 | K6: 15.6 | L6: 8.04 | M6: 1.1 | N6: 0.0559
A7: 3 | B7: Teagan Quitoriano | C7: ARI | D7: DAL | E7: 4300 | G7: 1400 | I7: 0.0667 | J7: 0.4 | K7: 0 | L7: 0.4 | M7: 0.09 | N7: 0
A8: 4 | B8: Tyler Warren | C8: IND | D8: JAC | E8: 5500 | G8: 200 | I8: 0.3333 | J8: 2 | K8: 10.2 | L8: 5.28 | M8: 0.96 | N8: 0.0142
A9: 5 | B9: Sam LaPorta | C9: DET | D9: MIN | E9: 5700 | F9: 53.5 | G9: 220 | H9: 4.5 | I9: 0.3125 | J9: 9.48 | K9: 9.8 | L9: 9.61 | M9: 1.69 | N9: 0.146
A10: 6 | B10: Mike Gesicki | C10: CIN | D10: TEN | E10: 5300 | G10: 220 | I10: 0.3125 | J10: 1.88 | K10: 5.9 | L10: 3.49 | M10: 0.66 | N10: 0.0009
A11: 7 | B11: Travis Kelce | C11: KC | D11: DEN | E11: 5400 | G11: 205 | I11: 0.3279 | J11: 1.97 | K11: 8.5 | L11: 4.58 | M11: 0.85 | N11: 0.007
A12: 8 | B12: T.J. Hockenson | C12: MIN | D12: DET | E12: 5200 | F12: 37 | G12: 300 | H12: 4.5 | I12: 0.25 | J12: 7.45 | K12: 9.8 | L12: 8.39 | M12: 1.61 | N12: 0.1016
A13: 9 | B13: Dalton Kincaid | C13: BUF | D13: BAL | E13: 5600 | G13: 180 | I13: 0.3571 | J13: 2.14 | K13: 8.1 | L13: 4.53 | M13: 0.81 | N13: 0.0063
A14: 10 | B14: Pat Freiermuth | C14: PIT | D14: CLE | E14: 5000 | G14: 280 | I14: 0.2632 | J14: 1.58 | K14: 7.9 | L14: 4.11 | M14: 0.82 | N14: 0.0039
A15: 11 | B15: Brenton Strange | C15: JAC | D15: IND | E15: 5100 | G15: 235 | I15: 0.2985 | J15: 1.79 | K15: 8.9 | L15: 4.63 | M15: 0.91 | N15: 0.008
A16: 12 | B16: Hunter Henry | C16: NE | D16: MIA | E16: 5200 | G16: 190 | I16: 0.3448 | J16: 2.07 | K16: 9.6 | L16: 5.08 | M16: 0.98 | N16: 0.0127
A17: 13 | B17: Harold Fannin Jr. | C17: CLE | D17: PIT | E17: 5500 | G17: 205 | I17: 0.3279 | J17: 1.97 | K17: 7.9 | L17: 4.34 | M17: 0.79 | N17: 0.005
A18: 14 | B18: Kyle Pitts Sr. | C18: ATL | D18: TB | E18: 5300 | G18: 220 | I18: 0.3125 | J18: 1.88 | K18: 9.3 | L18: 4.85 | M18: 0.91 | N18: 0.0098
A19: 15 | B19: Michael Mayer | C19: LV | D19: NYJ | E19: 4800 | G19: 290 | I19: 0.2564 | J19: 1.54 | K19: 6.4 | L19: 3.48 | M19: 0.73 | N19: 0.001
A20: 16 | B20: Tyler Higbee | C20: LAR | D20: LAC | E20: 4700 | G20: 180 | I20: 0.3571 | J20: 2.14 | K20: 5.8 | L20: 3.61 | M20: 0.77 | N20: 0.0015
A21: 17 | B21: Mason Taylor | C21: NYJ | D21: LV | E21: 5000 | G21: 290 | I21: 0.2564 | J21: 1.54 | K21: 7.9 | L21: 4.08 | M21: 0.82 | N21: 0.0038
A22: 18 | B22: Greg Dulcich | C22: MIA | D22: NE | E22: 5100 | G22: 300 | I22: 0.25 | J22: 1.5 | K22: 7.1 | L22: 3.74 | M22: 0.73 | N22: 0.0019
A23: 19 | B23: Darnell Washington | C23: PIT | D23: CLE | E23: 4800 | G23: 240 | I23: 0.2941 | J23: 1.76 | K23: 6 | L23: 3.46 | M23: 0.72 | N23: 0.0009
A24: 20 | B24: Ryan Miller | C24: NE | D24: MIA | E24: 4200 | I24: 0.2941 | J24: 0 | K24: 0 | L24: 0 | M24: 0 | N24: 0.08
A25: 21 | B25: Kenyon Sadiq | C25: NYJ | D25: LV | E25: 4900 | G25: 350 | I25: 0.2222 | J25: 1.33 | K25: 4.4 | L25: 2.56 | M25: 0.52 | N25: 0
A26: 22 | B26: Mark Andrews | C26: BAL | D26: BUF | E26: 5200 | G26: 220 | I26: 0.3125 | J26: 1.88 | K26: 8.7 | L26: 4.61 | M26: 0.89 | N26: 0.0076
A27: 23 | B27: Terrance Ferguson | C27: LAR | D27: LAC | E27: 4900 | I27: 0.1905 | J27: 0 | K27: 0 | L27: 0 | M27: 0 | N27: 0.08
A28: 24 | B28: Matt Hibner | C28: BAL | D28: BUF | E28: 4200 | I28: 0.1481 | J28: 0 | K28: 1.6 | L28: 1.6 | M28: 0.38 | N28: 0
A29: 25 | B29: Jake Ferguson | C29: DAL | D29: ARI | E29: 5400 | G29: 200 | I29: 0.3333 | J29: 2 | K29: 4.9 | L29: 3.16 | M29: 0.59 | N29: 0.0001
A30: 26 | B30: Eli Raridon | C30: NE | D30: MIA | E30: 4500 | G30: 190 | I30: 0.3448 | J30: 2.07 | K30: 7.2 | L30: 4.12 | M30: 0.92 | N30: 0.0046
A31: 27 | B31: David Njoku | C31: LAC | D31: LAR | E31: 4700 | I31: 0.2564 | J31: 0 | K31: 0 | L31: 0 | M31: 0 | N31: 0.08
A32: 28 | B32: Nate Adkins | C32: DEN | D32: KC | E32: 4100 | G32: 1100 | I32: 0.0833 | J32: 0.5 | K32: 0 | L32: 0.5 | M32: 0.12 | N32: 0
A33: 29 | B33: Elijah Higgins | C33: ARI | D33: DAL | E33: 4600 | G33: 550 | I33: 0.1538 | J33: 0.92 | K33: 3.8 | L33: 2.07 | M33: 0.45 | N33: 0
A34: 30 | B34: Josh Cuevas | C34: BAL | D34: BUF | E34: 4400 | G34: 800 | I34: 0.1111 | J34: 0.67 | K34: 1.6 | L34: 1.04 | M34: 0.24 | N34: 0
A35: 31 | B35: Cade Otton | C35: TB | D35: ATL | E35: 4800 | G35: 230 | I35: 0.303 | J35: 1.82 | K35: 6.4 | L35: 3.65 | M35: 0.76 | N35: 0.0016
A36: 32 | B36: Colby Parkinson | C36: LAR | D36: LAC | E36: 5100 | G36: 240 | I36: 0.2941 | J36: 1.76 | K36: 7.9 | L36: 4.22 | M36: 0.83 | N36: 0.0046
A37: 33 | B37: Oronde Gadsden II | C37: LAC | D37: LAR | E37: 5000 | G37: 500 | I37: 0.1667 | J37: 1 | K37: 3.4 | L37: 1.96 | M37: 0.39 | N37: 0
A38: 34 | B38: Evan Engram | C38: DEN | D38: KC | E38: 4900 | G38: 450 | I38: 0.1818 | J38: 1.09 | K38: 4.5 | L38: 2.45 | M38: 0.5 | N38: 0
A39: 35 | B39: Jeremy Ruckert | C39: NYJ | D39: LV | E39: 4300 | G39: 1400 | I39: 0.0667 | J39: 0.4 | K39: 0 | L39: 0.4 | M39: 0.09 | N39: 0
A40: 36 | B40: Noah Gray | C40: KC | D40: DEN | E40: 4400 | G40: 550 | I40: 0.1538 | J40: 0.92 | K40: 3.2 | L40: 1.83 | M40: 0.42 | N40: 0
A41: 37 | B41: Davis Allen | C41: LAR | D41: LAC | E41: 4400 | G41: 240 | I41: 0.2941 | J41: 1.76 | K41: 4.3 | L41: 2.78 | M41: 0.63 | N41: 0
A42: 38 | B42: Drew Sample | C42: CIN | D42: TEN | E42: 4500 | G42: 300 | I42: 0.25 | J42: 1.5 | K42: 2.2 | L42: 1.78 | M42: 0.4 | N42: 0
...

Sheet Defenses (D_ST)
A1: Defense & Special Teams (D/ST) Model
A4: Rank | B4: Team Defense | C4: Team | D4: Opponent | E4: Salary | F4: Opponent Total | G4: Projected Score | H4: Value | I4: Projected Ownership | J4: Value | K4: Projected Ownership
A5: 1 | B5: Vikings | C5: MIN | D5: DET | E5: 4300 | F5: 23 | G5: 7.2 | H5: 1.67 | I5: 0.0116 | J5: 1.86 | K5: 0.019
A6: 2 | B6: Bengals | C6: CIN | D6: TEN | E6: 4800 | F6: 23.25 | G6: 7.11 | H6: 1.48 | I6: 0.0096 | J6: 1.47 | K6: 0.014
A7: 3 | B7: Buccaneers | C7: TB | D7: ATL | E7: 3900 | F7: 23 | G7: 7.2 | H7: 1.85 | I7: 0.0132 | J7: 1.39 | K7: 0.0102
A8: 4 | B8: Steelers | C8: PIT | D8: CLE | E8: 4900 | F8: 19.5 | G8: 8.43 | H8: 1.72 | I8: 0.0165 | J8: 1.57 | K8: 0.0119
A9: 5 | B9: Broncos | C9: DEN | D9: KC | E9: 4100 | F9: 20.75 | G9: 7.99 | H9: 1.95 | I9: 0.0174 | J9: 2.07 | K9: 0.0204
A10: 6 | B10: Chiefs | C10: KC | D10: DEN | E10: 4600 | F10: 20.75 | G10: 7.99 | H10: 1.74 | I10: 0.015 | J10: 1.64 | K10: 0.0133
A11: 7 | B11: Jaguars | C11: JAC | D11: IND | E11: 4700 | F11: 23.25 | G11: 7.11 | H11: 1.51 | I11: 0.0099 | J11: 1.63 | K11: 0.0143
A12: 8 | B12: Patriots | C12: NE | D12: MIA | E12: 5000 | F12: 22.25 | G12: 7.46 | H12: 1.49 | I12: 0.0107 | J12: 1.35 | K12: 0.0096
A13: 9 | B13: Titans | C13: TEN | D13: CIN | E13: 3300 | F13: 23.25 | G13: 7.11 | H13: 2.16 | I13: 0.0157 | J13: 1.78 | K13: 0.0137
A14: 10 | B14: Browns | C14: CLE | D14: PIT | E14: 4200 | F14: 19.5 | G14: 8.43 | H14: 2.01 | I14: 0.0202 | J14: 2.2 | K14: 0.0238
A15: 11 | B15: Falcons | C15: ATL | D15: TB | E15: 3700 | F15: 23 | G15: 7.2 | H15: 1.95 | I15: 0.0141 | J15: 1.86 | K15: 0.017
A16: 12 | B16: Jets | C16: NYJ | D16: LV | E16: 3800 | F16: 22.5 | G16: 7.38 | H16: 1.94 | I16: 0.0148 | J16: 1.83 | K16: 0.0148
... A30: 26 | B30: Dolphins | C30: MIA | D30: NE | E30: 3000 | F30: 22.25 | G30: 7.46 | H30: 2.49 | I30: 0.0208 | J30: 2.33 | K30: 0.0253

Sheet Removed Players
A1: Source Sheet | B1: Position | C1: Player | D1: Team | E1: Original Rank | F1: Removal Reason
A2: Quarterbacks (QB) | B2: QB | C2: Dillon Gabriel | D2: CLE | E2: 28 | F2: Not in top-2 Week 1 depth-chart role
A3: Quarterbacks (QB) | B3: QB | C3: Cooper Rush | D3: ATL | E3: 29 | F3: Not in top-2 Week 1 depth-chart role
A4: Quarterbacks (QB) | B4: QB | C4: J.J. McCarthy | D4: MIN | E4: 30 | F4: Not in top-2 Week 1 depth-chart role
A5: Quarterbacks (QB) | B5: QB | C5: Joey Aguilar | D5: JAC | E5: 32 | F5: Not in top-2 Week 1 depth-chart role
A6: Quarterbacks (QB) | B6: QB | C6: Skylar Thompson | D6: BAL | E6: 34 | F6: Not in top-2 Week 1 depth-chart role
A7: Quarterbacks (QB) | B7: QB | C7: Joe Fagnano | D7: BAL | E7: 36 | F7: Not in top-2 Week 1 depth-chart role
A8: Quarterbacks (QB) | B8: QB | C8: Cam Miller | D8: MIA | E8: 37 | F8: Not in top-2 Week 1 depth-chart role
A9: Quarterbacks (QB) | B9: QB | C9: Cole Payton | D9: PHI | E9: 39 | F9: Not in top-2 Week 1 depth-chart role
A10: Quarterbacks (QB) | B10: QB | C10: Nick Mullens | D10: JAC | E10: 40 | F10: Not in top-2 Week 1 depth-chart role
A11: Quarterbacks (QB) | B11: QB | C11: Sam Hartman | D11: WAS | E11: 42 | F11: Not in top-2 Week 1 depth-chart role
A12: Quarterbacks (QB) | B12: QB | C12: Bailey Zappe | D12: NYJ | E12: 44 | F12: Not in top-2 Week 1 depth-chart role
A13: Quarterbacks (QB) | B13: QB | C13: Drew Allar | D13: PIT | E13: 45 | F13: Not in top-2 Week 1 depth-chart role
... A435: Tight Ends (TE) | B435: TE | C435: Nick Muse | D435: ATL | E435: 168 | F435: Not in top-2 Week 1 depth-chart role
